Workbook
Name EME: #REF!
Name globalesA: #REF!

Sheet Hoja1
A2: Anio | B2: SMLV | C2: V SM | D2: IPC | F2: V SM*IPC
A3: 2021 | B3: 908526 | C3: 10.07 | D3: 5.62 | F3: 0.042132172
A4: 2022 | B4: 1000000 | C4: 16 | D4: 13.12 | F4: 0.025459689
A5: 2023 | B5: 1160000 | C5: 12.07 | D5: 9.28 | F5: 0.025530747
A6: 2024 | B6: 1300000 | C6: 13 | D6: 9.28 | F6: 0.025530747

Sheet Tasas=>
B2: Hoja
B3: Tasa_OBP
B4: Tasa

Sheet Tasa_OBP
A1: h | B1: t | C1: tt | D1: k | E1: int | F1: int_ | G1: (1+deslizamiento)^(k-1) | H1: inff = (1+inf)^(k-1), | I1: intte = (1+int)^(k-1+((tt+1)/12)), | J1: v_OBP | L1: inf | M1: int | N1: Deslizamiento
A2: 0 | B2: 0 | C2: =+B2-1 -> -1 | D2: 0 | E2: =1+$N$2 -> 1 | F2: =+(1+$L$2)*(1+E2) -> 2.199 | G2: =+(1+$N$3)^(D2-1) -> 0.98357431 | H2: =+(1+$L$2)^D2-1 -> 0 | I2: =+(1+F2)^(D2-1+((C2+1)/12)) -> 0.31259769 | J2: =1/I2 -> 3.199 | L2: =+((3*0.0928)+(2*0.1312)+(0.0562))/6 -> 0.0995 | M2: 0.0004 | N2: 0
A3: 1 | B3: 1 | C3: =+B3-1 -> 0 | D3: =+ROUNDUP(A3/12,0) -> 1 | E3: =1+$N$3 -> 1.0167 | F3: =+(1+$L$2)*(1+E3) -> 2.2173616 | G3: =+(1+$N$3)^(D3-1) -> 1 | H3: =+(1+$L$2)^D3-1 -> 0.0995 | I3: =+(1+F3)^(D3-1+((C3+1)/12)) -> 1.1022793 | J3: =1/I3 -> 0.90721107 | N3: 0.0167
A4: 2 | B4: 2 | C4: =+B4-1 -> 1 | D4: =+ROUNDUP(A4/12,0) -> 1 | E4: =1+$N$3 -> 1.0167 | F4: =+(1+$L$2)*(1+E4) -> 2.2173616 | G4: =+(1+$N$3)^(D4-1) -> 1 | H4: =+(1+$L$2)^D4-1 -> 0.0995 | I4: =+(1+F4)^(D4-1+((C4+1)/12)) -> 1.2150197 | J4: =1/I4 -> 0.82303193
A5: 3 | B5: 3 | C5: =+B5-1 -> 2 | D5: =+ROUNDUP(A5/12,0) -> 1 | E5: =1+$N$3 -> 1.0167 | F5: =+(1+$L$2)*(1+E5) -> 2.2173616 | G5: =+(1+$N$3)^(D5-1) -> 1 | H5: =+(1+$L$2)^D5-1 -> 0.0995 | I5: =+(1+F5)^(D5-1+((C5+1)/12)) -> 1.3392911 | J5: =1/I5 -> 0.74666369
A6: 4 | B6: 4 | C6: =+B6-1 -> 3 | D6: =+ROUNDUP(A6/12,0) -> 1 | E6: =1+$N$3 -> 1.0167 | F6: =+(1+$L$2)*(1+E6) -> 2.2173616 | G6: =+(1+$N$3)^(D6-1) -> 1 | H6: =+(1+$L$2)^D6-1 -> 0.0995 | I6: =+(1+F6)^(D6-1+((C6+1)/12)) -> 1.4762728 | J6: =1/I6 -> 0.67738156
A7: 5 | B7: 5 | C7: =+B7-1 -> 4 | D7: =+ROUNDUP(A7/12,0) -> 1 | E7: =1+$N$3 -> 1.0167 | F7: =+(1+$L$2)*(1+E7) -> 2.2173616 | G7: =+(1+$N$3)^(D7-1) -> 1 | H7: =+(1+$L$2)^D7-1 -> 0.0995 | I7: =+(1+F7)^(D7-1+((C7+1)/12)) -> 1.627265 | J7: =1/I7 -> 0.61452806 | L7: infobp = 0.0928
A8: 6 | B8: 6 | C8: =+B8-1 -> 5 | D8: =+ROUNDUP(A8/12,0) -> 1 | E8: =1+$N$3 -> 1.0167 | F8: =+(1+$L$2)*(1+E8) -> 2.2173616 | G8: =+(1+$N$3)^(D8-1) -> 1 | H8: =+(1+$L$2)^D8-1 -> 0.0995 | I8: =+(1+F8)^(D8-1+((C8+1)/12)) -> 1.7937005 | J8: =1/I8 -> 0.55750666
A9: 7 | B9: 7 | C9: =+B9-1 -> 6 | D9: =+ROUNDUP(A9/12,0) -> 1 | E9: =1+$N$3 -> 1.0167 | F9: =+(1+$L$2)*(1+E9) -> 2.2173616 | G9: =+(1+$N$3)^(D9-1) -> 1 | H9: =+(1+$L$2)^D9-1 -> 0.0995 | I9: =+(1+F9)^(D9-1+((C9+1)/12)) -> 1.977159 | J9: =1/I9 -> 0.50577622
A10: 8 | B10: 8 | C10: =+B10-1 -> 7 | D10: =+ROUNDUP(A10/12,0) -> 1 | E10: =1+$N$3 -> 1.0167 | F10: =+(1+$L$2)*(1+E10) -> 2.2173616 | G10: =+(1+$N$3)^(D10-1) -> 1 | H10: =+(1+$L$2)^D10-1 -> 0.0995 | I10: =+(1+F10)^(D10-1+((C10+1)/12)) -> 2.1793815 | J10: =1/I10 -> 0.45884578
A11: 9 | B11: 9 | C11: =+B11-1 -> 8 | D11: =+ROUNDUP(A11/12,0) -> 1 | E11: =1+$N$3 -> 1.0167 | F11: =+(1+$L$2)*(1+E11) -> 2.2173616 | G11: =+(1+$N$3)^(D11-1) -> 1 | H11: =+(1+$L$2)^D11-1 -> 0.0995 | I11: =+(1+F11)^(D11-1+((C11+1)/12)) -> 2.4022871 | J11: =1/I11 -> 0.41626998
A12: 10 | B12: 10 | C12: =+B12-1 -> 9 | D12: =+ROUNDUP(A12/12,0) -> 1 | E12: =1+$N$3 -> 1.0167 | F12: =+(1+$L$2)*(1+E12) -> 2.2173616 | G12: =+(1+$N$3)^(D12-1) -> 1 | H12: =+(1+$L$2)^D12-1 -> 0.0995 | I12: =+(1+F12)^(D12-1+((C12+1)/12)) -> 2.6479914 | J12: =1/I12 -> 0.37764473
A13: 11 | B13: 11 | C13: =+B13-1 -> 10 | D13: =+ROUNDUP(A13/12,0) -> 1 | E13: =1+$N$3 -> 1.0167 | F13: =+(1+$L$2)*(1+E13) -> 2.2173616 | G13: =+(1+$N$3)^(D13-1) -> 1 | H13: =+(1+$L$2)^D13-1 -> 0.0995 | I13: =+(1+F13)^(D13-1+((C13+1)/12)) -> 2.9188261 | J13: =1/I13 -> 0.34260348
A14: 12 | B14: 12 | C14: =+B14-1 -> 11 | D14: =+ROUNDUP(A14/12,0) -> 1 | E14: =1+$N$3 -> 1.0167 | F14: =+(1+$L$2)*(1+E14) -> 2.2173616 | G14: =+(1+$N$3)^(D14-1) -> 1 | H14: =+(1+$L$2)^D14-1 -> 0.0995 | I14: =+(1+F14)^(D14-1+((C14+1)/12)) -> 3.2173616 | J14: =1/I14 -> 0.31081368
A15: 13 | B15: 1 | C15: =+B15-1 -> 0 | D15: =+ROUNDUP(A15/12,0) -> 2 | E15: =1+$N$3 -> 1.0167 | F15: =+(1+$L$2)*(1+E15) -> 2.2173616 | G15: =+(1+$N$3)^(D15-1) -> 1.0167 | H15: =+(1+$L$2)^D15-1 -> 0.20890025 | I15: =+(1+F15)^(D15-1+((C15+1)/12)) -> 3.5464312 | J15: =1/I15 -> 0.28197361
A16: 14 | B16: 2 | C16: =+B16-1 -> 1 | D16: =+ROUNDUP(A16/12,0) -> 2 | E16: =1+$N$3 -> 1.0167 | F16: =+(1+$L$2)*(1+E16) -> 2.2173616 | G16: =+(1+$N$3)^(D16-1) -> 1.0167 | H16: =+(1+$L$2)^D16-1 -> 0.20890025 | I16: =+(1+F16)^(D16-1+((C16+1)/12)) -> 3.9091577 | J16: =1/I16 -> 0.25580958
A17: 15 | B17: 3 | C17: =+B17-1 -> 2 | D17: =+ROUNDUP(A17/12,0) -> 2 | E17: =1+$N$3 -> 1.0167 | F17: =+(1+$L$2)*(1+E17) -> 2.2173616 | G17: =+(1+$N$3)^(D17-1) -> 1.0167 | H17: =+(1+$L$2)^D17-1 -> 0.20890025 | I17: =+(1+F17)^(D17-1+((C17+1)/12)) -> 4.3089837 | J17: =1/I17 -> 0.23207328
A18: 16 | B18: 4 | C18: =+B18-1 -> 3 | D18: =+ROUNDUP(A18/12,0) -> 2 | E18: =1+$N$3 -> 1.0167 | F18: =+(1+$L$2)*(1+E18) -> 2.2173616 | G18: =+(1+$N$3)^(D18-1) -> 1.0167 | H18: =+(1+$L$2)^D18-1 -> 0.20890025 | I18: =+(1+F18)^(D18-1+((C18+1)/12)) -> 4.7497036 | J18: =1/I18 -> 0.21053945
A19: 17 | B19: 5 | C19: =+B19-1 -> 4 | D19: =+ROUNDUP(A19/12,0) -> 2 | E19: =1+$N$3 -> 1.0167 | F19: =+(1+$L$2)*(1+E19) -> 2.2173616 | G19: =+(1+$N$3)^(D19-1) -> 1.0167 | H19: =+(1+$L$2)^D19-1 -> 0.20890025 | I19: =+(1+F19)^(D19-1+((C19+1)/12)) -> 5.2355 | J19: =1/I19 -> 0.19100372
... A979: 977 | B979: 5 | C979: =+B979-1 -> 4 | D979: =+ROUNDUP(A979/12,0) -> 82 | E979: =1+$N$3 -> 1.0167 | F979: =+(1+$L$2)*(1+E979) -> 2.2173616 | G979: =+(1+$N$3)^(D979-1) -> 3.8248879 | H979: =+(1+$L$2)^D979-1 -> 2386.8617 | I979: =+(1+F979)^(D979-1+((C979+1)/12)) -> 2.0842443e+41 | J979: =1/I979 -> 4.7979019e-42
A980: 978 | B980: 6 | C980: =+B980-1 -> 5 | D980: =+ROUNDUP(A980/12,0) -> 82 | F980: =+(1+$L$2)*(1+E980) -> 1.0995 | G980: =+(1+$N$3)^(D980-1) -> 3.8248879 | H980: =+(1+$L$2)^D980-1 -> 2386.8617 | I980: =+(1+F980)^(D980-1+((C980+1)/12)) -> 1.7883155e+26 | J980: =1/I980 -> 5.5918545e-27
A981: 979 | B981: 7 | C981: =+B981-1 -> 6 | D981: =+ROUNDUP(A981/12,0) -> 82 | F981: =+(1+$L$2)*(1+E981) -> 1.0995 | G981: =+(1+$N$3)^(D981-1) -> 3.8248879 | H981: =+(1+$L$2)^D981-1 -> 2386.8617 | I981: =+(1+F981)^(D981-1+((C981+1)/12)) -> 1.9023356e+26 | J981: =1/I981 -> 5.2566961e-27
A982: 980 | B982: 8 | C982: =+B982-1 -> 7 | D982: =+ROUNDUP(A982/12,0) -> 82 | F982: =+(1+$L$2)*(1+E982) -> 1.0995 | G982: =+(1+$N$3)^(D982-1) -> 3.8248879 | H982: =+(1+$L$2)^D982-1 -> 2386.8617 | I982: =+(1+F982)^(D982-1+((C982+1)/12)) -> 2.0236254e+26 | J982: =1/I982 -> 4.9416261e-27
A983: 981 | B983: 9 | C983: =+B983-1 -> 8 | D983: =+ROUNDUP(A983/12,0) -> 82 | F983: =+(1+$L$2)*(1+E983) -> 1.0995 | G983: =+(1+$N$3)^(D983-1) -> 3.8248879 | H983: =+(1+$L$2)^D983-1 -> 2386.8617 | I983: =+(1+F983)^(D983-1+((C983+1)/12)) -> 2.1526484e+26 | J983: =1/I983 -> 4.6454404e-27
A984: 982 | B984: 10 | C984: =+B984-1 -> 9 | D984: =+ROUNDUP(A984/12,0) -> 82 | F984: =+(1+$L$2)*(1+E984) -> 1.0995 | G984: =+(1+$N$3)^(D984-1) -> 3.8248879 | H984: =+(1+$L$2)^D984-1 -> 2386.8617 | I984: =+(1+F984)^(D984-1+((C984+1)/12)) -> 2.2898978e+26 | J984: =1/I984 -> 4.3670072e-27
A985: 983 | B985: 11 | C985: =+B985-1 -> 10 | D985: =+ROUNDUP(A985/12,0) -> 82 | F985: =+(1+$L$2)*(1+E985) -> 1.0995 | G985: =+(1+$N$3)^(D985-1) -> 3.8248879 | H985: =+(1+$L$2)^D985-1 -> 2386.8617 | I985: =+(1+F985)^(D985-1+((C985+1)/12)) -> 2.4358979e+26 | J985: =1/I985 -> 4.1052623e-27
A986: 984 | B986: 12 | C986: =+B986-1 -> 11 | D986: =+ROUNDUP(A986/12,0) -> 82 | F986: =+(1+$L$2)*(1+E986) -> 1.0995 | G986: =+(1+$N$3)^(D986-1) -> 3.8248879 | H986: =+(1+$L$2)^D986-1 -> 2386.8617 | I986: =+(1+F986)^(D986-1+((C986+1)/12)) -> 2.5912068e+26 | J986: =1/I986 -> 3.8592057e-27
A987: 985 | B987: 1 | C987: =+B987-1 -> 0 | D987: =+ROUNDUP(A987/12,0) -> 83 | F987: =+(1+$L$2)*(1+E987) -> 1.0995 | G987: =+(1+$N$3)^(D987-1) -> 3.8887635 | H987: =+(1+$L$2)^D987-1 -> 2624.4539 | I987: =+(1+F987)^(D987-1+((C987+1)/12)) -> 2.7564179e+26 | J987: =1/I987 -> 3.6278969e-27
A988: 986 | B988: 2 | C988: =+B988-1 -> 1 | D988: =+ROUNDUP(A988/12,0) -> 83 | F988: =+(1+$L$2)*(1+E988) -> 1.0995 | G988: =+(1+$N$3)^(D988-1) -> 3.8887635 | H988: =+(1+$L$2)^D988-1 -> 2624.4539 | I988: =+(1+F988)^(D988-1+((C988+1)/12)) -> 2.9321626e+26 | J988: =1/I988 -> 3.410452e-27
A989: 987 | B989: 3 | C989: =+B989-1 -> 2 | D989: =+ROUNDUP(A989/12,0) -> 83 | F989: =+(1+$L$2)*(1+E989) -> 1.0995 | G989: =+(1+$N$3)^(D989-1) -> 3.8887635 | H989: =+(1+$L$2)^D989-1 -> 2624.4539 | I989: =+(1+F989)^(D989-1+((C989+1)/12)) -> 3.1191125e+26 | J989: =1/I989 -> 3.2060401e-27
A990: 988 | B990: 4 | C990: =+B990-1 -> 3 | D990: =+ROUNDUP(A990/12,0) -> 83 | F990: =+(1+$L$2)*(1+E990) -> 1.0995 | G990: =+(1+$N$3)^(D990-1) -> 3.8887635 | H990: =+(1+$L$2)^D990-1 -> 2624.4539 | I990: =+(1+F990)^(D990-1+((C990+1)/12)) -> 3.3179821e+26 | J990: =1/I990 -> 3.0138801e-27
A991: 989 | B991: 5 | C991: =+B991-1 -> 4 | D991: =+ROUNDUP(A991/12,0) -> 83 | F991: =+(1+$L$2)*(1+E991) -> 1.0995 | G991: =+(1+$N$3)^(D991-1) -> 3.8887635 | H991: =+(1+$L$2)^D991-1 -> 2624.4539 | I991: =+(1+F991)^(D991-1+((C991+1)/12)) -> 3.5295312e+26 | J991: =1/I991 -> 2.8332375e-27
... A1334: 1332 | B1334: 12 | C1334: =+B1334-1 -> 11 | D1334: =+ROUNDUP(A1334/12,0) -> 111 | F1334: =+(1+$L$2)*(1+E1334) -> 1.0995 | G1334: =+(1+$N$3)^(D1334-1) -> 6.1831615 | H1334: =+(1+$L$2)^D1334-1 -> 37381.724 | I1334: =+(1+F1334)^(D1334-1+((C1334+1)/12)) -> 5.6867294e+35 | J1334: =1/I1334 -> 1.75848e-36

Sheet Tasa
A1: Año | B1: Crecimiento_anual_IPC | C1: deslizamiento | D1: Crecimiento_acum_IPC | E1: crecimiento_anual_SLM_ESC0 | F1: Crecimiento_acum_ESC0 | G1: v_Crecimiento_acum_IPC | H1: v_Crecimiento_acum_ESC | I1: v_Crecimiento_acum_IPC_desc | J1: v_Crecimiento_acum_ESC_desc | K1: =+Tasa_OBP!J1 -> v_OBP | L1: IPC | M1: Deslizamiento
A2: 0 | B2: =1+L2 -> 1 | C2: 1 | D2: =+PRODUCT($B$2:B2) -> 1 | E2: =+D2*C2 -> 1 | F2: =+PRODUCT($E$2:E2) -> 1 | G2: =1/D2 -> 1 | H2: =1/F2 -> 1 | I2: =G2^A2 -> 1 | J2: =H2^A2 -> 1 | K2: 1 | L2: 0 | M2: 0
A3: 1 | B3: =1+L3 -> 1.0545 | C3: =1+$M$3 -> 1.0167 | D3: =+PRODUCT($B$2:B3) -> 1.0545 | E3: =+B3*C3 -> 1.0721101 | F3: =+PRODUCT($E$2:E3) -> 1.0721101 | G3: =1/D3 -> 0.94831674 | H3: =1/F3 -> 0.93273998 | I3: =G3^A3 -> 0.94831674 | J3: =H3^A3 -> 0.93273998 | K3: =+Tasa_OBP!J3 -> 0.90721107 | L3: 0.0545 | M3: 0.0167
A4: 2 | B4: =1+L4 -> 1.0346 | C4: =1+$M$3 -> 1.0167 | D4: =+PRODUCT($B$2:B4) -> 1.0909857 | E4: =+B4*C4 -> 1.0518778 | F4: =+PRODUCT($E$2:E4) -> 1.1277289 | G4: =1/D4 -> 0.9166023 | H4: =1/F4 -> 0.88673795 | I4: =G4^A4 -> 0.84015977 | J4: =H4^A4 -> 0.78630419 | K4: =+Tasa_OBP!J4 -> 0.82303193 | L4: 0.0346
A5: 3 | B5: =1+$L$5 -> 1.03 | C5: =1+$M$3 -> 1.0167 | D5: =+PRODUCT($B$2:B5) -> 1.1237153 | E5: =+B5*C5 -> 1.047201 | F5: =+PRODUCT($E$2:E5) -> 1.1809588 | G5: =1/D5 -> 0.88990514 | H5: =1/F5 -> 0.84676958 | I5: =G5^A5 -> 0.70474362 | J5: =H5^A5 -> 0.60714964 | K5: =+Tasa_OBP!J5 -> 0.74666369 | L5: 0.03
A6: 4 | B6: =1+$L$5 -> 1.03 | C6: =1+$M$3 -> 1.0167 | D6: =+PRODUCT($B$2:B6) -> 1.1574267 | E6: =+B6*C6 -> 1.047201 | F6: =+PRODUCT($E$2:E6) -> 1.2367013 | G6: =1/D6 -> 0.86398558 | H6: =1/F6 -> 0.80860272 | I6: =G6^A6 -> 0.55721907 | J6: =H6^A6 -> 0.4275046 | K6: =+Tasa_OBP!J6 -> 0.67738156
A7: 5 | B7: =1+$L$5 -> 1.03 | C7: =1+$M$3 -> 1.0167 | D7: =+PRODUCT($B$2:B7) -> 1.1921495 | E7: =+B7*C7 -> 1.047201 | F7: =+PRODUCT($E$2:E7) -> 1.2950748 | G7: =1/D7 -> 0.83882095 | H7: =1/F7 -> 0.77215618 | I7: =G7^A7 -> 0.41528509 | J7: =H7^A7 -> 0.27448951 | K7: =+Tasa_OBP!J7 -> 0.61452806
A8: 6 | B8: =1+$L$5 -> 1.03 | C8: =1+$M$3 -> 1.0167 | D8: =+PRODUCT($B$2:B8) -> 1.227914 | E8: =+B8*C8 -> 1.047201 | F8: =+PRODUCT($E$2:E8) -> 1.3562036 | G8: =1/D8 -> 0.81438927 | H8: =1/F8 -> 0.73735241 | I8: =G8^A8 -> 0.2917375 | J8: =H8^A8 -> 0.16071285 | K8: =+Tasa_OBP!J8 -> 0.55750666
A9: 7 | B9: =1+$L$5 -> 1.03 | C9: =1+$M$3 -> 1.0167 | D9: =+PRODUCT($B$2:B9) -> 1.2647514 | E9: =+B9*C9 -> 1.047201 | F9: =+PRODUCT($E$2:E9) -> 1.4202178 | G9: =1/D9 -> 0.79066919 | H9: =1/F9 -> 0.70411736 | I9: =G9^A9 -> 0.1931807 | J9: =H9^A9 -> 0.085805549 | K9: =+Tasa_OBP!J9 -> 0.50577622
A10: 8 | B10: =1+$L$5 -> 1.03 | C10: =1+$M$3 -> 1.0167 | D10: =+PRODUCT($B$2:B10) -> 1.302694 | E10: =+B10*C10 -> 1.047201 | F10: =+PRODUCT($E$2:E10) -> 1.4872535 | G10: =1/D10 -> 0.76763999 | H10: =1/F10 -> 0.67238034 | I10: =G10^A10 -> 0.12057597 | J10: =H10^A10 -> 0.041775345 | K10: =+Tasa_OBP!J10 -> 0.45884578
A11: 9 | B11: =1+$L$5 -> 1.03 | C11: =1+$M$3 -> 1.0167 | D11: =+PRODUCT($B$2:B11) -> 1.3417748 | E11: =+B11*C11 -> 1.047201 | F11: =+PRODUCT($E$2:E11) -> 1.5574533 | G11: =1/D11 -> 0.74528155 | H11: =1/F11 -> 0.64207381 | I11: =G11^A11 -> 0.070938715 | J11: =H11^A11 -> 0.018546613 | K11: =+Tasa_OBP!J11 -> 0.41626998
A12: 10 | B12: =1+$L$5 -> 1.03 | C12: =1+$M$3 -> 1.0167 | D12: =+PRODUCT($B$2:B12) -> 1.382028 | E12: =+B12*C12 -> 1.047201 | F12: =+PRODUCT($E$2:E12) -> 1.6309667 | G12: =1/D12 -> 0.72357432 | H12: =1/F12 -> 0.61313331 | I12: =G12^A12 -> 0.039339736 | J12: =H12^A12 -> 0.0075084291 | K12: =+Tasa_OBP!J12 -> 0.37764473
A13: 11 | B13: =1+$L$5 -> 1.03 | C13: =1+$M$3 -> 1.0167 | D13: =+PRODUCT($B$2:B13) -> 1.4234889 | E13: =+B13*C13 -> 1.047201 | F13: =+PRODUCT($E$2:E13) -> 1.7079499 | G13: =1/D13 -> 0.70249934 | H13: =1/F13 -> 0.58549725 | I13: =G13^A13 -> 0.020563883 | J13: =H13^A13 -> 0.0027718739 | K13: =+Tasa_OBP!J13 -> 0.34260348
A14: 12 | B14: =1+$L$5 -> 1.03 | C14: =1+$M$3 -> 1.0167 | D14: =+PRODUCT($B$2:B14) -> 1.4661936 | E14: =+B14*C14 -> 1.047201 | F14: =+PRODUCT($E$2:E14) -> 1.7885669 | G14: =1/D14 -> 0.68203819 | H14: =1/F14 -> 0.55910685 | I14: =G14^A14 -> 0.010132214 | J14: =H14^A14 -> 0.00093312053 | K14: =+Tasa_OBP!J14 -> 0.31081368
A15: 13 | B15: =1+$L$5 -> 1.03 | C15: =1+$M$3 -> 1.0167 | D15: =+PRODUCT($B$2:B15) -> 1.5101794 | E15: =+B15*C15 -> 1.047201 | F15: =+PRODUCT($E$2:E15) -> 1.872989 | G15: =1/D15 -> 0.662173 | H15: =1/F15 -> 0.53390595 | I15: =G15^A15 -> 0.0047057528 | J15: =H15^A15 -> 0.00028644545 | K15: =+Tasa_OBP!J15 -> 0.28197361
A16: 14 | B16: =1+$L$5 -> 1.03 | C16: =1+$M$3 -> 1.0167 | D16: =+PRODUCT($B$2:B16) -> 1.5554847 | E16: =+B16*C16 -> 1.047201 | F16: =+PRODUCT($E$2:E16) -> 1.961396 | G16: =1/D16 -> 0.64288641 | H16: =1/F16 -> 0.50984095 | I16: =G16^A16 -> 0.0020600579 | J16: =H16^A16 -> 8.0183686e-05 | K16: =+Tasa_OBP!J16 -> 0.25580958
A17: 15 | B17: =1+$L$5 -> 1.03 | C17: =1+$M$3 -> 1.0167 | D17: =+PRODUCT($B$2:B17) -> 1.6021493 | E17: =+B17*C17 -> 1.047201 | F17: =+PRODUCT($E$2:E17) -> 2.0539758 | G17: =1/D17 -> 0.62416156 | H17: =1/F17 -> 0.48686064 | I17: =G17^A17 -> 0.00085007121 | J17: =H17^A17 -> 2.0467746e-05 | K17: =+Tasa_OBP!J17 -> 0.23207328
... A979: 977 | B979: =1+$L$5 -> 1.03 | C979: =1+$M$3 -> 1.0167 | D979: =+PRODUCT($B$2:B979) -> 3.5818974e+12 | E979: =+B979*C979 -> 1.047201 | F979: =+PRODUCT($E$2:E979) -> 3.8150634e+19 | G979: =1/D979 -> 2.7918164e-13 | H979: =1/F979 -> 2.6211884e-20 | I979: =G979^A979 -> 0 | J979: =H979^A979 -> 0 | K979: =+Tasa_OBP!J979 -> 4.7979019e-42

Sheet Resumen_F394=>
B2: Hoja
B3: Resumen_RSV_2024

Sheet Resumen_RSV_2024
A2: RM | B2: Invalidez-vejez | C2: Sobrevivencia | D2: Auxilios Funerarios | E2: Total Reserva | I2: Invalidez | J2: Vejez | K2: Sobrevivencia | L2: Total | O2: Invalidez | P2: Vejez | Q2: Sobrevivencia | R2: Total
A3: Valor | B3: 2193976.1 | C3: 5317286.1 | D3: 24873.722 | E3: =+SUM(B3:D3) -> 7536136 | H3: Total | I3: 7586 | J3: 514 | K3: 12438 | L3: 20538 | N3: Total | O3: 7586 | P3: 514 | Q3: 12438 | R3: 20538
A4: Porcentaje | B4: =+B3/$E$3 -> 0.29112746 | C4: =+C3/$E$3 -> 0.70557194 | D4: =+D3/$E$3 -> 0.0033005936 | E4: =+E3/$E$3 -> 1 | N4: Porcentaje | O4: =+O3/$E$10 -> 0.36936411 | P4: =+P3/$E$10 -> 0.02502678 | Q4: =+Q3/$E$10 -> 0.60560911 | R4: =+R3/$E$10 -> 1
B9: Invalidez | C9: Vejez | D9: Sobrevivencia | E9: Total
A10: Total | B10: 7586 | C10: 514 | D10: 12438 | E10: 20538
A11: Porcentaje | B11: =+B10/$E$10 -> 0.36936411 | C11: =+C10/$E$10 -> 0.02502678 | D11: =+D10/$E$10 -> 0.60560911 | E11: =+E10/$E$10 -> 1

Sheet Modelo_Fase=>
B2: Hojas
B3: Actualizacion cuadro 2024
B4: Parametros_1
B5: Parametros_2
B6: Parametros_3

Sheet Actualizacion cuadro 2024
E1: Con deslizamiento
A2: Tipo | B2: Descripción | C2: TOTAL | D2: Fecha de Corte | E2: Crecimiento Salario Mínimo | F2: Inflación | G2: Deslizamiento | H2: Crecimiento primer año IPC | I2: Crecimiento 2do año IPC | J2: IPC desde el 3er año | K2: Rango | L2: Salario Mín | M2: Codigo | N2: Archivo excel | O2: DIF | R2: 1 | S2: 2 | T2: 3 | U2: 4 | V2: 5 | W2: 6 | X2: 7 | Y2: 8 | Z2: 9 | AA2: 10 | AB2: 11 | AC2: 12 | AD2: 13 | AE2: 14 | AF2: 15 | AG2: 16 | AH2: 17
A3: base f394 | B3: Reservas (ene2024) | C3: 7822344.6 | D3: 45321 | E3: =+Parametros_1!$C$29/100 -> 0.0016 | F3: =+Parametros_1!$D$29/100 -> 0.001312 | H3: =+(1+G4)*(H4+1)-1 -> 0.039116667 | I3: =+(1+G4)*(1+I4)*(H4+1)-1 -> 0.079676854 | J3: =+(1+G4)*(1+J4)*(1+I4)*(H4+1)-1 -> 0.11206716 | M3: calculo_pension.R | N3: FT394_ENE_2024.xlsx | Q3: Tasa | R3: 0 | S3: =+H6 -> 0.036633333 | T3: =+I6 -> 0.034566667 | U3: =+$J$6 -> 0.03 | V3: =+$J$6 -> 0.03 | W3: =+$J$6 -> 0.03 | X3: =+$J$6 -> 0.03 | Y3: =+$J$6 -> 0.03 | Z3: =+$J$6 -> 0.03 | AA3: =+$J$6 -> 0.03 | AB3: =+$J$6 -> 0.03 | ... AH3: =+$J$6 -> 0.03
A4: sin_desli | B4: Estimación sin deslizamiento (ene2024) | C4: 8263113.9 | D4: 45322 | G4: 0 | H4: =+Parametros_2!$D$44 -> 0.039116667 | I4: =+Parametros_2!$D$45 -> 0.039033333 | J4: 0.03 | K4: 2024:3000 | L4: 1300000 | M4: calculo_pension.R | N4: FT394_ENE_2024.xlsx | O4: =+C4/C3-1 -> 0.056347464 | P4: 0.0032724637 | Q4: IPC | R4: 0.01 | S4: =(1+S3) -> 1.0366333 | T4: =S4*(1+T3) -> 1.0724663 | U4: =T4*(1+U3) -> 1.1046403 | V4: =U4*(1+V3) -> 1.1377795 | W4: =V4*(1+W3) -> 1.1719129 | X4: =W4*(1+X3) -> 1.2070703 | Y4: =X4*(1+Y3) -> 1.2432824 | Z4: =Y4*(1+Z3) -> 1.2805808 | AA4: =Z4*(1+AA3) -> 1.3189983 | ... AH4: =AG4*(1+AH3) -> 1.6222015
A5: con_desl | B5: Con cambio en deslizamiento (ene2024) | C5: 9378867.9 | D5: 45322 | G5: =+Parametros_1!$H$35 -> 0.017572009 | H5: =+Parametros_2!$D$44 -> 0.039116667 | I5: =+Parametros_2!$D$45 -> 0.039033333 | J5: 0.03 | K5: 2024:3000 | L5: 1300000 | M5: calculo_pension.R | N5: FT394_ENE_2024.xlsx | O5: =+C5/C4-1 -> 0.13502828 | P5: 0.17551604 | Q5: SMLV | R5: =+L4 -> 1300000 | S5: =+$R$5*S4 -> 1347623.3 | T5: =+$R$5*T4 -> 1394206.2 | U5: =+$R$5*U4 -> 1436032.4 | V5: =+$R$5*V4 -> 1479113.3 | W5: =+$R$5*W4 -> 1523486.7 | X5: =+$R$5*X4 -> 1569191.3 | Y5: =+$R$5*Y4 -> 1616267.1 | Z5: =+$R$5*Z4 -> 1664755.1 | ... AH5: =+$R$5*AH4 -> 2108861.9
A6: con_desl_IPC | B6: Con cambio en aumentos IPC (ene 2024) | C6: 9379124.4 | D6: 45322 | G6: =+Parametros_1!$H$35 -> 0.017572009 | H6: =+Parametros_3!$D$34 -> 0.036633333 | I6: =+Parametros_3!$D$35 -> 0.034566667 | J6: 0.03 | K6: 2024:3000 | L6: 1300000 | M6: calculo_pension.R | N6: FT394_ENE_2024.xlsx | O6: =+C6/C5-1 -> 2.734433e-05 | P6: 0.0001718577 | Q6: ESC0 | R6: 0.01 | S6: =(1+S3)*(1+0.0167) -> 1.0539451 | T6: =S6*(1+T3)*(1+0.0167) -> 1.1085858 | U6: =T6*(1+U3)*(1+0.0167) -> 1.1609121 | V6: =U6*(1+V3)*(1+0.0167) -> 1.2157083 | W6: =V6*(1+W3)*(1+0.0167) -> 1.273091 | X6: =W6*(1+X3)*(1+0.0167) -> 1.3331822 | Y6: =X6*(1+Y3)*(1+0.0167) -> 1.3961097 | Z6: =Y6*(1+Z3)*(1+0.0167) -> 1.4620075 | AA6: =Z6*(1+AA3)*(1+0.0167) -> 1.5310157 | ... AH6: =AG6*(1+AH3)*(1+0.0167) -> 2.1144137
A7: con_desl_fch_corte | B7: Con cambio en fecha de corte (ene2025) | C7: 9196527.6 | D7: 45688 | G7: =+Parametros_1!$H$35 -> 0.017572009 | H7: =+Parametros_3!$D$34 -> 0.036633333 | I7: =+Parametros_3!$D$35 -> 0.034566667 | J7: 0.03 | K7: 2024:3000 | L7: 1300000 | M7: calculo_pension-SLMV.R | N7: FT394_ENE_2024.xlsx-fecha-corte | O7: =+C7/C6-1 -> -0.019468431 | P7: -0.0029316993 | Q7: SMLV | R7: =+L4 -> 1300000 | S7: =+$R$7*S6 -> 1370128.6 | T7: =+$R$7*T6 -> 1441161.5 | U7: =+$R$5*T6 -> 1441161.5 | V7: =+$R$5*V6 -> 1580420.8 | W7: =+$R$5*W6 -> 1655018.3 | X7: =+$R$5*X6 -> 1733136.8 | Y7: =+$R$5*Y6 -> 1814942.6 | Z7: =+$R$5*Z6 -> 1900609.7 | AA7: =+$R$5*AA6 -> 1990320.4 | AB7: =+$R$5*AB6 -> 2084265.5 | AC7: =+$R$5*AC6 -> 2182644.9 | ... AH7: =+$R$5*AH6 -> 2748737.9
A8: con_desl_cam_mesa | B8: Con cambios en valor de la mesada (ene2025) | C8: 10207390 | D8: 45688 | E8: =+Parametros_1!$C$30/100 -> 0.001207 | F8: =+Parametros_1!$D$30/100 -> 0.000928 | G8: =+Parametros_1!$H$35 -> 0.017572009 | H8: =+Parametros_3!$D$34 -> 0.036633333 | I8: =+Parametros_3!$D$35 -> 0.034566667 | J8: 0.03 | K8: 2025:3000 | L8: 1456910 | M8: calculo_pension-SLMV.R | N8: data/FT394_ENE_2024 - cambio 13SMMLV.xlsx-fecha-corte | O8: =+C8/C7-1 -> 0.10991785 | P8: 0.14515941 | Q8: Deslizamiento | R8: =+R7-R5 -> 0 | S8: =+S7-S5 -> 22505.31 | T8: =+T7-T5 -> 46955.317 | U8: =+U7-U5 -> 5129.1312 | V8: =+V7-V5 -> 101307.5 | W8: =+W7-W5 -> 131531.54 | X8: =+X7-X5 -> 163945.46 | Y8: =+Y7-Y5 -> 198675.51 | ... AH8: =+AH7-AH5 -> 639875.93
A9: con_desl_cam_mesa2 | B9: Con cambios en valor de la mesada (ene2024) | C9: 9640286.1 | D9: 45688 | E9: 0.2 | F9: =+Parametros_1!D30/100 -> 0.000928 | G9: =+Parametros_1!$H$35 -> 0.017572009 | H9: =+Parametros_3!$D$34 -> 0.036633333 | I9: =+Parametros_3!$D$35 -> 0.034566667 | J9: 0.03 | K9: 2025:3000 | L9: 1560000 | M9: calculo_pension-SLMV.R | N9: data/FT394_ENE_2024 - cambio 20SMMLV.xlsx-fecha-corte | O9: =+C9/C8-1 -> -0.055558184 | P9: 0.025482684
Q10: =+Parametros_1!$H$35 -> 0.017572009 | R10: =+R8/R5 -> 0 | S10: =+S8/S5 -> 0.0167 | T10: =+T8/T5 -> 0.03367889 | U10: =+U8/U5 -> 0.0035717379 | V10: =+V8/V5 -> 0.068492048 | W10: =+W8/W5 -> 0.086335865 | X10: =+X8/X5 -> 0.10447767 | Y10: =+Y8/Y5 -> 0.12292245 | ... AH10: =+AH8/AH5 -> 0.30342239
E11: Sin deslizamiento
A12: Tipo | B12: Descripción | C12: TOTAL | D12: Fecha de Corte | E12: Crecimiento Salario mínimo | F12: Inflación | G12: Deslizamiento | H12: Crecimiento primer año IPC | I12: Crecimiento 2do año IPC | J12: IPC desde el 3er año | K12: Rango | L12: Salario Mín | M12: Codigo | O12: DIF
A13: base | B13: Reservas (ene2024) | C13: 7822344.6 | D13: 45321 | E13: =+Parametros_1!$C$29/100 -> 0.0016 | F13: =+Parametros_1!$D$29/100 -> 0.001312 | M13: calculo_pension.R | N13: FT394_ENE_2024.xlsx | O13: =+C13/C3-1 -> 0 | P13: 0
A14: sin_desli | B14: Estimación sin deslizamiento (ene2024) | C14: 8263113.9 | D14: 45322 | G14: 0 | H14: =+Parametros_2!$D$44 -> 0.039116667 | I14: =+Parametros_2!$D$45 -> 0.039033333 | J14: 0.03 | K14: 2024:3000 | L14: 1300000 | M14: calculo_pension.R | N14: FT394_ENE_2024.xlsx | O14: =+C14/C4-1 -> 0 | P14: 0
A15: sin_desl | B15: Con cambio en deslizamiento (ene2024) | C15: 8263113.9 | D15: 45322 | K15: 2024:3000 | N15: FT394_ENE_2024.xlsx | O15: =+C15/C5-1 -> -0.11896468 | P15: -0.14930978
A16: sin_desl_IPC | B16: Con cambio en aumentos IPC (ene 2024) | C16: 8263379.8 | D16: 45322 | G16: 0 | H16: =+Parametros_3!$D$34 -> 0.036633333 | I16: =+Parametros_3!$D$35 -> 0.034566667 | J16: 0.03 | K16: 2024:3000 | L16: 1300000 | M16: calculo_pension.R | N16: FT394_ENE_2024.xlsx | O16: =+C16/C6-1 -> -0.11896043 | P16: -0.14928888
A17: sin_desl_fch_corte | B17: Con cambio en fecha de corte (ene2025) | C17: 8122184 | D17: 45688 | G17: 0 | H17: =+Parametros_3!$D$34 -> 0.036633333 | I17: =+Parametros_3!$D$35 -> 0.034566667 | J17: 0.03 | K17: 2024:3000 | L17: 1300000 | M17: calculo_pension-SLMV.R | N17: FT394_ENE_2024.xlsx-fecha-corte | O17: =+C17/C7-1 -> -0.11682057 | P17: -0.15656251
A18: sin_desl_cam_mesa | B18: Con cambios en valor de la mesada (ene2025) | C18: 8953893.1 | D18: 45688 | E18: =+Parametros_1!$C$30/100 -> 0.001207 | F18: =+Parametros_1!$D$30/100 -> 0.000928 | G18: 0 | H18: =+Parametros_3!$D$34 -> 0.036633333 | I18: =+Parametros_3!$D$35 -> 0.034566667 | J18: 0.03 | K18: 2025:3000 | L18: 1456910 | M18: calculo_pension-SLMV.R | N18: data/FT394_ENE_2024 - cambio 13SMMLV.xlsx-fecha-corte | O18: =+C18/C8-1 -> -0.12280289 | P18: -0.15312434
A19: sin_desl_cam_mesa2 | B19: Con cambios en valor de la mesada (ene2024) | C19: 7946317.9 | D19: 45688 | E19: 0.2 | F19: =+F18 -> 0.000928 | G19: 0 | H19: =+Parametros_3!$D$34 -> 0.036633333 | I19: =+Parametros_3!$D$35 -> 0.034566667 | J19: 0.03 | K19: 2024:3000 | L19: 1560000 | M19: calculo_pension-SLMV.R | N19: data/FT394_ENE_2024 - cambio 20SMMLV.xlsx-fecha-corte | O19: =+C19/C9-1 -> -0.17571763 | P19: -0.15706544

Sheet Parametros_1
A1: AÑO | B1: Salario Mínimo | C1: Variación SM | D1: IPC | F1: MULT | G1: 100
A2: 1995 | C2: 0.195 | D2: 0.1946 | F2: =(((1+(C2/100))/(1+(D2/100)))-1)*100 -> 0.00039922311
A3: 1996 | C3: 0.21 | D3: 0.2163 | F3: =(((1+(C3/100))/(1+(D3/100)))-1)*100 -> -0.0062864025 | H3: =+(C3-D3) -> -0.0063
A4: 1997 | C4: 0.185 | D4: 0.1768 | F4: =(((1+(C4/100))/(1+(D4/100)))-1)*100 -> 0.008185528 | H4: =+(C4-D4) -> 0.0082
A5: 1998 | C5: 0.16 | D5: 0.167 | F5: =(((1+(C5/100))/(1+(D5/100)))-1)*100 -> -0.0069883295 | H5: =+(C5-D5) -> -0.007
A6: 1999 | B6: 260100 | C6: 0.1 | D6: 0.0923 | F6: =(((1+(C6/100))/(1+(D6/100)))-1)*100 -> 0.0076928995 | H6: =+(C6-D6) -> 0.0077
A7: 2000 | B7: 286000 | C7: 0.1 | D7: 0.0875 | F7: =(((1+(C7/100))/(1+(D7/100)))-1)*100 -> 0.012489072 | H7: =+(C7-D7) -> 0.0125
A8: 2001 | B8: 309000 | C8: 0.08 | D8: 0.0765 | F8: =(((1+(C8/100))/(1+(D8/100)))-1)*100 -> 0.0034973245 | H8: =+(C8-D8) -> 0.0035
A9: 2002 | B9: 332000 | C9: 0.074 | D9: 0.0699 | F9: =(((1+(C9/100))/(1+(D9/100)))-1)*100 -> 0.0040971361 | H9: =+(C9-D9) -> 0.0041
A10: 2003 | B10: 358000 | C10: 0.078 | D10: 0.0649 | F10: =(((1+(C10/100))/(1+(D10/100)))-1)*100 -> 0.013091504 | H10: =+(C10-D10) -> 0.0131
A11: 2004 | B11: 381500 | C11: 0.066 | D11: 0.055 | F11: =(((1+(C11/100))/(1+(D11/100)))-1)*100 -> 0.010993953 | H11: =+(C11-D11) -> 0.011
A12: 2005 | B12: 408000 | C12: 0.069 | D12: 0.0485 | F12: =(((1+(C12/100))/(1+(D12/100)))-1)*100 -> 0.020490062 | H12: =+(C12-D12) -> 0.0205
A13: 2006 | B13: 433700 | C13: 0.063 | D13: 0.0448 | F13: =(((1+(C13/100))/(1+(D13/100)))-1)*100 -> 0.01819185 | H13: =+(C13-D13) -> 0.0182
A14: 2007 | B14: 461500 | C14: 0.064 | D14: 0.0569 | F14: =(((1+(C14/100))/(1+(D14/100)))-1)*100 -> 0.0070959624 | H14: =+(C14-D14) -> 0.0071
A15: 2008 | B15: 496900 | C15: 0.077 | D15: 0.0767 | F15: =(((1+(C15/100))/(1+(D15/100)))-1)*100 -> 0.00029977008 | H15: =+(C15-D15) -> 0.0003
A16: 2009 | B16: 515000 | C16: 0.036 | D16: 0.02 | F16: =(((1+(C16/100))/(1+(D16/100)))-1)*100 -> 0.015996801 | H16: =+(C16-D16) -> 0.016
A17: 2010 | B17: 535600 | C17: 0.04 | D17: 0.0317 | F17: =(((1+(C17/100))/(1+(D17/100)))-1)*100 -> 0.0082973697 | H17: =+(C17-D17) -> 0.0083
... A30: 2023 | B30: 1300000 | C30: 0.1207 | D30: 0.0928 | F30: =(((1+(C30/100))/(1+(D30/100)))-1)*100 -> 0.027874133 | H30: =+(C30-D30) -> 0.0279
C31: 0.2 | D31: 0.0928
C32: =+B29*(1+C30) -> 1300012
A33: Cambio de mesadas
B34: SLMV | F34: 5 años | G34: 10 años | H34: 20 años | I34: todo
A35: SLMV 2024 | B35: =+B30 -> 1300000 | E35: =AVERAGE(F2:F28) -> 0.012424528 | F35: =AVERAGE(F25:F30) -> 0.028365173 | G35: =AVERAGE(F20:F30) -> 0.021642409 | H35: =AVERAGE(F10:F30) -> 0.017572009 | I35: =AVERAGE(F2:F30) -> 0.013520643 | K35: =AVERAGE(H10:H30) -> 0.017580952
A36: Varacion | B36: =+(1+((C30)/100))*$B$35 -> 1301569.1 | E36: Sin Imp COVID | H36: =AVERAGE(F10:F26) -> 0.014647284 | K36: =AVERAGE(H10:H26) -> 0.014652941
A37: Variacion estimada para 2024 | B37: =+(1+(INT(C31)/100))*$B$35 -> 1300000
H39: 157
H40: 167
H41: 147
H42: 131
H43: 141
H44: 51

Sheet Parametros_2
C4: Expectativas de Inflación
C6: Estadística | D6: Promedio | E6: Mínimo | F6: Máximo | G6: No. encuestados
C7: % mensual en enero de 2024 | D7: 0.0093297297 | E7: 0.0051 | F7: 0.0135 | G7: 40
C8: % anual en diciembre de 2024 | D8: 0.055000475 | E8: 0.044 | F8: 0.0781 | G8: 40
C9: % anual en enero de 2025 | D9: 0.051277973 | E9: 0.0396 | F9: 0.0721 | G9: 37
C10: % anual en diciembre de 2025 | D10: 0.038520385 | E10: 0.03 | F10: 0.061695 | G10: 39
C11: % anual en enero de 2026 | D11: 0.037120229 | E11: 0.0292 | F11: 0.061608 | G11: 35
C13: Expectativas de Inflación sin alimentos
C15: Estadística | D15: Promedio | E15: Mínimo | F15: Máximo | G15: No. encuestados
C16: % mensual en enero de 2024 | D16: 0.009621875 | E16: 0.006 | F16: 0.0147 | G16: 32
C17: % anual en diciembre de 2024 | D17: 0.05351875 | E17: 0.04 | F17: 0.0707 | G17: 32
C18: % anual en enero de 2025 | D18: 0.048736667 | E18: 0.0323 | F18: 0.068 | G18: 30
C19: % anual en diciembre de 2025 | D19: 0.037016129 | E19: 0.0253 | F19: 0.0522 | G19: 31
C20: % anual en enero de 2026 | D20: 0.034813793 | E20: 0.022 | F20: 0.0463 | G20: 29
C22: Expectativas de TRM fin de período
C24: Estadística | D24: Promedio | E24: Mínimo | F24: Máximo | G24: No. encuestados
C25: A enero de 2024 | D25: 3934.303 | E25: 3803 | F25: 4250 | G25: 37
C26: A diciembre de 2024 | D26: 4004.0026 | E26: 3339.5 | F26: 4400 | G26: 38
C27: A enero de 2025 | D27: 3985.7514 | E27: 3263.55 | F27: 4400 | G27: 36
C28: A diciembre de 2025 | D28: 3983.7275 | E28: 3119.19 | F28: 4500 | G28: 36
C29: A enero de 2026 | D29: 3973.4434 | E29: 3035.19 | F29: 4440 | G29: 32
C31: Expectativas Tasa de Intervención
C33: Estadística | D33: 45322 | E33: 45351 | F33: 45382 | G33: 45412 | H33: 45443 | I33: 45473 | J33: 45504 | K33: 45535 | L33: 45565 | M33: 45596 | N33: 45626 | O33: 45657 | P33: 45688 | Q33: 45716 | R33: 45747 | S33: 45777 | T33: 45808 | U33: 45838 | V33: 45869 | W33: 45900 | X33: 45930 | Y33: 45961 | Z33: 45991 | AA33: 46022 | AB33: 46053
C34: Promedio | D34: 0.12638158 | E34: 0.12605263 | F34: 0.12131579 | G34: 0.11598684 | H34: 0.11565789 | I34: 0.10907895 | J34: 0.10277027 | K34: 0.10256757 | L34: 0.095945946 | M34: 0.089594595 | N34: 0.089459459 | O34: 0.082763158 | P34: 0.078214286 | Q34: 0.077142857 | R34: 0.072357143 | S34: 0.068785714 | T34: 0.068285714 | U34: 0.065 | V34: 0.062357143 | W34: 0.061628571 | X34: 0.059214286 | Y34: 0.058382353 | Z34: 0.058382353 | AA34: 0.056928571 | AB34: 0.055808824
C35: Mínimo | D35: 0.125 | E35: 0.12 | F35: 0.115 | G35: 0.105 | H35: 0.105 | I35: 0.095 | J35: 0.085 | K35: 0.085 | L35: 0.08 | M35: 0.075 | N35: 0.075 | O35: 0.07 | P35: 0.065 | Q35: 0.055 | R35: 0.055 | S35: 0.05 | T35: 0.05 | U35: 0.045 | V35: 0.045 | W35: 0.045 | X35: 0.045 | Y35: 0.045 | Z35: 0.045 | AA35: 0.045 | AB35: 0.045
C36: Máximo | D36: 0.13 | E36: 0.13 | F36: 0.1275 | G36: 0.1225 | H36: 0.1225 | I36: 0.1175 | J36: 0.115 | K36: 0.1125 | L36: 0.1075 | M36: 0.1025 | N36: 0.1025 | O36: 0.0975 | P36: 0.0975 | Q36: 0.095 | R36: 0.09 | S36: 0.09 | T36: 0.09 | U36: 0.09 | V36: 0.09 | W36: 0.08 | X36: 0.0775 | Y36: 0.075 | Z36: 0.075 | AA36: 0.075 | AB36: 0.075
C38: Expectativas de Inflación de los Cinco Mejores Informantes
C40: Estadística | D40: Promedio
C41: % mensual en enero de 2024 | D41: 0.0094166667
C42: % anual en diciembre de 2024 | D42: 0.051666667
C43: % anual en enero de 2025 | D43: 0.047283333
C44: % anual en diciembre de 2025 | D44: 0.039116667
C45: % anual en enero de 2026 | D45: 0.039033333
C47: Fecha corte: | D47: res_inf_ene2024 | F47: https://www.banrep.gov.co/es/resultados-mensuales-expectativas-analistas-economicos?field_date_format_value=All&page=0%22

Sheet Parametros_3
C1: RESUMEN, RESULTADOS DE LA ENCUESTA MENSUAL DE EXPECTATIVAS ECONÓMICAS
C2: Fecha de realización: del 10 de abril al 12 de abril de 2024
C3: Expectativas de Inflación
C4: Estadística | D4: Promedio | E4: Mínimo | F4: Máximo | G4: No. encuestados
C5: % mensual en abril de 2024 | D5: 0.0056641026 | E5: 0.0039 | F5: 0.0071 | G5: 40
C6: % anual en diciembre de 2024 | D6: 0.056209756 | E6: 0.044 | F6: 0.0705 | G6: 41
C7: % anual en abril de 2025 | D7: 0.046659519 | E7: 0.0358 | F7: 0.0686 | G7: 41
C8: % anual en diciembre de 2025 | D8: 0.039007143 | E8: 0.03 | F8: 0.0613 | G8: 42
C9: % anual en abril de 2026 | D9: 0.036124324 | E9: 0.03 | F9: 0.0571 | G9: 37
C10: Expectativas de Inflación sin alimentos
C11: Estadística | D11: Promedio | E11: Mínimo | F11: Máximo | G11: No. encuestados
C12: % mensual en abril de 2024 | D12: 0.0052606061 | E12: 0.0023 | F12: 0.0069 | G12: 33
C13: % anual en diciembre de 2024 | D13: 0.056548571 | E13: 0.043 | F13: 0.0643 | G13: 35
C14: % anual en abril de 2025 | D14: 0.044567315 | E14: 0.034 | F14: 0.0558 | G14: 34
C15: % anual en diciembre de 2025 | D15: 0.037020588 | E15: 0.0253 | F15: 0.0514 | G15: 34
C16: % anual en abril de 2026 | D16: 0.03467957 | E16: 0.025 | F16: 0.0513 | G16: 31
C17: Expectativas de TRM fin de período
C18: Estadística | D18: Promedio | E18: Mínimo | F18: Máximo | G18: No. encuestados
C19: A abril de 2024 | D19: 3844.7112 | E19: 3750 | F19: 3945 | G19: 41
C20: A diciembre de 2024 | D20: 3999.3764 | E20: 3700 | F20: 4264 | G20: 42
C21: A abril de 2025 | D21: 3987.4834 | E21: 3500 | F21: 4250 | G21: 41
C22: A diciembre de 2025 | D22: 4020.2465 | E22: 3400 | F22: 4415 | G22: 40
C23: A abril de 2026 | D23: 4021.1397 | E23: 3400 | F23: 4500 | G23: 37
C24: Expectativas Tasa de Intervención
C25: Estadística | D25: 45412 | E25: 45443 | F25: 45473 | G25: 45504 | H25: 45535 | I25: 45565 | J25: 45596 | K25: 45626 | L25: 45657 | M25: 45688 | N25: 45716 | O25: 45747 | P25: 45777 | Q25: 45808 | R25: 45838 | S25: 45869 | T25: 45900 | U25: 45930 | V25: 45961 | W25: 45991 | X25: 46022 | Y25: 46053 | Z25: 46081 | AA25: 46112 | AB25: 46142
C26: Promedio | D26: 0.11743902 | E26: 0.11743902 | F26: 0.11164634 | G26: 0.1053125 | H26: 0.1051875 | I26: 0.0984375 | J26: 0.0918125 | K26: 0.09175 | L26: 0.084390244 | M26: 0.07925 | N26: 0.07875 | O26: 0.0735 | P26: 0.069375 | Q26: 0.0693125 | R26: 0.065192308 | S26: 0.061858974 | T26: 0.061410256 | U26: 0.058974359 | V26: 0.057628205 | W26: 0.057628205 | X26: 0.055875 | Y26: 0.05472973 | Z26: 0.054189189 | AA26: 0.053243243 | AB26: 0.052635135
C27: Mínimo | D27: 0.115 | E27: 0.115 | F27: 0.1075 | G27: 0.1 | H27: 0.1 | I27: 0.09 | J27: 0.0825 | K27: 0.0825 | L27: 0.075 | M27: 0.07 | N27: 0.07 | O27: 0.06 | P27: 0.06 | Q27: 0.06 | R27: 0.0525 | S27: 0.05 | T27: 0.05 | U27: 0.0475 | V27: 0.0425 | W27: 0.0425 | X27: 0.0425 | Y27: 0.04 | Z27: 0.04 | AA27: 0.03 | AB27: 0.03
C28: Máximo | D28: 0.1225 | E28: 0.1225 | F28: 0.12 | G28: 0.1125 | H28: 0.1125 | I28: 0.1075 | J28: 0.105 | K28: 0.105 | L28: 0.1 | M28: 0.1 | N28: 0.09 | O28: 0.09 | P28: 0.09 | Q28: 0.09 | R28: 0.08 | S28: 0.08 | T28: 0.075 | U28: 0.075 | V28: 0.07 | W28: 0.07 | X28: 0.07 | Y28: 0.07 | Z28: 0.0675 | AA28: 0.0675 | AB28: 0.0675
C29: Expectativas de Inflación de los Cinco Mejores Informantes
C30: Estadística | D30: Promedio
C31: % mensual en abril de 2024 | D31: 0.00582
C32: % anual en diciembre de 2024 | D32: 0.054466667 | E32: 1er
C33: % anual en abril de 2025 | D33: 0.04175
C34: % anual en diciembre de 2025 | D34: 0.036633333 | E34: 2do
C35: % anual en abril de 2026 | D35: 0.034566667
C44: Fecha corte: | D44: res_inf_abr2024 | F44: https://www.banrep.gov.co/es/resultados-mensuales-expectativas-analistas-economicos?field_date_format_value=All&page=0%22

Sheet Resutados=>
B2: Hojas
B3: RSV_CIA
B4: Res_CIA
B5: Res_CIA_TPO
B6: RSV_CIA_TPO
B7: CIA_OBP

Sheet RSV_CIA
A1: Con cambios en valor de la mesada (ene2024) | B1: Deslizamiento-multiplicativo | K1: Con cambios en valor de la mesada (ene2024) | L1: Deslizamiento-aditivo
A2: COMPANIA | B2: 0 | C2: 0.0177 | D2: 0.016742824 | E2: 0.0157 | F2: =+G2+0.001 -> 0.0151 | G2: 0.0141 | H2: 0.0131 | K2: COMPANIA | L2: 0 | M2: 0.0177 | N2: 0.016742824 | O2: 0.0157 | P2: =+Q2+0.001 -> 0.0151 | Q2: 0.0141 | R2: 0.0131
A3: ALFA | B3: 68699.821 | C3: 77228.524 | D3: 76606.004 | E3: 76001.751 | F3: 75647.706 | G3: 75071.852 | H3: 74513.221 | I3: =+B19-D3 -> -11339.236 | J3: =+I3/B19 -> -0.17373674 | K3: ALFA | L3: 68699.821 | M3: 76886.416 | N3: 76292.487 | O3: 75715.34 | P3: 75377.154 | Q3: 74826.492 | R3: 74291.918 | S3: =+B19-N3 -> -11025.719 | T3: =+S3/B19 -> -0.16893312
A4: ALLIANZ | B4: 106207.44 | C4: 113342.3 | D4: 112793.24 | E4: 112263.38 | F4: 111954.38 | G4: 111454.25 | H4: 110971.93 | I4: =+B20-D4 -> -1658.7201 | J4: =+I4/B20 -> -0.014925337 | K4: ALLIANZ | L4: 106207.44 | M4: 113040.49 | N4: 112518.12 | O4: 112013.55 | P4: 111719.14 | Q4: 111242.18 | R4: 110781.9 | S4: =+B20-N4 -> -1383.6077 | T4: =+S4/B20 -> -0.012449847
A5: AURORA | B5: 7855.8126 | C5: 9913.5702 | D5: 9773.9594 | E5: 9637.365 | F5: 9556.8231 | G5: 9424.9749 | H5: 9295.9493 | I5: =+B21-D5 -> -346.63254 | J5: =+I5/B21 -> -0.036768911 | K5: AURORA | L5: 7855.8126 | M5: 9836.8977 | N5: 9703.1295 | O5: 9572.1601 | P5: 9494.931 | Q5: 9368.3809 | R5: 9244.4677 | S5: =+B21-N5 -> -275.8026 | T5: =+S5/B21 -> -0.029255652
A6: BBVA SEGUROS | B6: 62716.593 | C6: 66615.608 | D6: 66200.986 | E6: 65805.442 | F6: 65577.052 | G6: 65215.654 | H6: 64873.705 | I6: =+B22-D6 -> -9110.0905 | J6: =+I6/B22 -> -0.15957169 | K6: BBVA SEGUROS | L6: 62716.593 | M6: 66389.576 | N6: 65997.163 | O6: 65622.537 | P6: 65407.868 | Q6: 65066.47 | R6: 64742.762 | S6: =+B22-N6 -> -8906.2678 | T6: =+S6/B22 -> -0.15600155
A7: BOLIVAR | B7: 792631.1 | C7: 871559.12 | D7: 863807.44 | E7: 856373.58 | F7: 852063.68 | G7: 845082.62 | H7: 838435.75 | I7: =+B23-D7 -> -166345.34 | J7: =+I7/B23 -> -0.2385009 | K7: BOLIVAR | L7: 792631.1 | M7: 867349.67 | N7: 859977.46 | O7: 852936.18 | P7: 848826.71 | Q7: 842192.9 | R7: 835865.11 | S7: =+B23-N7 -> -162515.36 | T7: =+S7/B23 -> -0.2330096
A8: COLMENA | B8: 845199.08 | C8: 934872.11 | D8: 928201.5 | E8: 921757.55 | F8: 917996.74 | G8: 911899.77 | H8: 906010.18 | I8: =+B24-D8 -> -104742.52 | J8: =+I8/B24 -> -0.12719823 | K8: COLMENA | L8: 845199.08 | M8: 931213.65 | N8: 924863.14 | O8: 918722.32 | P8: 915135.28 | Q8: 909315.86 | R8: 903688.8 | S8: =+B24-N8 -> -101404.17 | T8: =+S8/B24 -> -0.12314416
A9: COLPATRIA | B9: 925881.73 | C9: 1113372.6 | D9: 1099903.6 | E9: 1086822.6 | F9: 1079155.5 | G9: 1066673.9 | H9: 1054555 | I9: =+B25-D9 -> 35454.814 | J9: =+I9/B25 -> 0.03122786 | K9: COLPATRIA | L9: 925881.73 | M9: 1105996.4 | N9: 1093138.2 | O9: 1080639.3 | P9: 1073309.3 | Q9: 1061368.2 | R9: 1049764.2 | S9: =+B25-N9 -> 42220.212 | T9: =+S9/B25 -> 0.037186681
A10: EQUIDAD | B10: 278522.49 | C10: 344346.62 | D10: 339767.12 | E10: 335304.51 | F10: 332681.8 | G10: 328400.12 | H10: 324227.83 | I10: =+B26-D10 -> -67869.216 | J10: =+I10/B26 -> -0.24961287 | K10: EQUIDAD | L10: 278522.49 | M10: 341836.66 | N10: 337457.39 | O10: 333186.64 | P10: 330675.28 | Q10: 326572.7 | R10: 322572.05 | S10: =+B26-N10 -> -65559.487 | T10: =+S10/B26 -> -0.24111803
A11: GLOBAL | B11: 6926.4949 | C11: 7164.7374 | D11: 7141.762 | E11: 7119.5788 | F11: 7106.6352 | G11: 7086.0183 | H11: 7066.2175 | I11: =+B27-D11 -> -1195.5532 | J11: =+I11/B27 -> -0.20106142 | K11: GLOBAL | L11: 6926.4949 | M11: 7152.2043 | N11: 7130.333 | O11: 7109.1832 | P11: 7096.9759 | Q11: 7077.3983 | R11: 7058.5249 | S11: =+B27-N11 -> -1184.1242 | T11: =+S11/B27 -> -0.19913936
A12: MAPFRE | B12: 82500.844 | C12: 97965.259 | D12: 96844.491 | E12: 95755.997 | F12: 95117.631 | G12: 94078.044 | H12: 93068.8 | I12: =+B28-D12 -> -11891.446 | J12: =+I12/B28 -> -0.13997668 | K12: MAPFRE | L12: 82500.844 | M12: 97351.854 | N12: 96281.761 | O12: 95241.498 | P12: 94630.866 | Q12: 93636.629 | R12: 92670.075 | S12: =+B28-N12 -> -11328.716 | T12: =+S12/B28 -> -0.13335267
A13: POSITIVA | B13: 2147278 | C13: 2590030.1 | D13: 2558000.1 | E13: 2526927.3 | F13: 2508733.1 | G13: 2479145.2 | H13: 2450458.2 | I13: =+B29-D13 -> -590521.17 | J13: =+I13/B29 -> -0.30014104 | K13: POSITIVA | L13: 2147278 | M13: 2572526.7 | N13: 2541963.3 | O13: 2512288.5 | P13: 2494902.9 | Q13: 2466610.3 | R13: 2439157.8 | S13: =+B29-N13 -> -574484.41 | T13: =+S13/B29 -> -0.29199012
A14: SURA | B14: 2773517.1 | C14: 3086569.1 | D14: 3056207.9 | E14: 3026931.3 | F14: 3009878.3 | G14: 2982578.4 | H14: 2956384.9 | I14: =+B30-D14 -> -463338.42 | J14: =+I14/B30 -> -0.17869716 | K14: SURA | L14: 2773517.1 | M14: 3070114.5 | N14: 3041217.5 | O14: 3013336.7 | P14: 2997198 | Q14: 2971236.2 | R14: 2946280.1 | S14: =+B30-N14 -> -448347.97 | T14: =+S14/B30 -> -0.17291575
A15: Total | B15: =+SUM(B2:B14) -> 8097936.5 | C15: =+SUM(C2:C14) -> 9312979.7 | D15: =+SUM(D2:D14) -> 9215248.1 | E15: =+SUM(E2:E14) -> 9120700.3 | F15: =+SUM(F2:F14) -> 9065469.3 | G15: =+SUM(G2:G14) -> 8976110.9 | H15: =+SUM(H2:H14) -> 8889861.7 | I15: =+B31-D15 -> -1392903.5 | J15: =+I15/B31 -> -0.17806727 | K15: Total | L15: =+SUM(L2:L14) -> 8097936.5 | M15: =+SUM(M2:M14) -> 9259695.1 | N15: =+SUM(N2:N14) -> 9166540 | O15: =+SUM(O2:O14) -> 9076384 | P15: =+SUM(P2:P14) -> 9023774.4 | Q15: =+SUM(Q2:Q14) -> 8938513.7 | R15: =+SUM(R2:R14) -> 8856117.7 | S15: =+B31-N15 -> -1344195.4 | T15: =+S15/B31 -> -0.17184048
L16: =+L15-B15 -> 0 | M16: =+M15-$L$15 -> 1161758.6 | N16: =+N15-$L$15 -> 1068603.5 | O16: =+O15-$L$15 -> 978447.45 | P16: =+P15-$L$15 -> 925837.86 | Q16: =+Q15-$L$15 -> 840577.2 | R16: =+R15-$L$15 -> 758181.2
A17: Reserva-2024-01-31 | E17: OBP-2023
A18: COMPANIA | B18: 44592 | E18: Etiquetas de fila | F18: Suma de R1 | G18: Suma de R2 | H18: Suma de Cobertura_AF
A19: ALFA | B19: 65266.768 | E19: 1401 | F19: 94504.603 | G19: 93872.378 | H19: 5.7947358
A20: ALLIANZ | B20: 111134.52 | E20: 1404 | F20: 799256.81 | G20: 783776.85 | H20: 59.23213
A21: AURORA | B21: 9427.3269 | E21: 1407 | F21: 634233.63 | G21: 625552.46 | H21: 53.472878
A22: BBVA SEGUROS | B22: 57090.895 | E22: 1411 | F22: 2002684.1 | G22: 1968023 | H22: 167.47989
A23: BOLIVAR | B23: 697462.1 | E23: 1417 | F23: 59304.468 | G23: 58513.382 | H23: 4.6089349
A24: COLMENA | B24: 823458.98 | E24: 1420 | F24: 5319.2225 | G24: 5289.1988 | H24: 0.39037054
A25: COLPATRIA | B25: 1135358.4 | E25: 1423 | F25: 1876993.3 | G25: 1844636.9 | H25: 139.26095
A26: EQUIDAD | B26: 271897.91 | E26: 1425 | F26: 733594.91 | G26: 726525.72 | H26: 44.161858
A27: GLOBAL | B27: 5946.2088 | E27: 1426 | F27: 49376.27 | G27: 48947.784 | H27: 2.4374083
A28: MAPFRE | B28: 84953.045 | E28: 1429 | F28: 251787.12 | G28: 246573.78 | H28: 21.884005
A29: POSITIVA | B29: 1967478.9 | E29: 1430 | F29: 73131.283 | G29: 72028.28 | H29: 8.5812666
A30: SURA | B30: 2592869.5 | E30: Total general | F30: 6580185.8 | G30: 6473739.7 | H30: 507.30442
A31: Total | B31: =+SUM(B19:B30) -> 7822344.6

Sheet Res_CIA
A1: Desliza | B1: 0 | C1: =+H18 -> 0.0177 | D1: =+H17 -> 0.016742824 | E1: =+H16 -> 0.0157 | F1: 0.0151 | G1: 0.0141 | H1: 0.0131
A2: Tasa | B2: Sin deslizamiento | C2: Con deslizamiento + 10 pt basico | D2: Con deslizamiento | E2: Con deslizamiento - 10 pt basico | F2: Con deslizamiento + 10 pt basico | G2: Con deslizamiento | H2: Con deslizamiento - 10 pt basico
A3: multiplicativo | B3: =+RSV_CIA!B15 -> 8097936.5 | C3: =+RSV_CIA!C15 -> 9312979.7 | D3: =+RSV_CIA!D15 -> 9215248.1 | E3: =+RSV_CIA!E15 -> 9120700.3 | F3: =+RSV_CIA!F15 -> 9065469.3 | G3: =+RSV_CIA!G15 -> 8976110.9 | H3: =+RSV_CIA!H15 -> 8889861.7
C4: =+C3/$B$3-1 -> 0.15004355 | D4: =+D3/$B$3-1 -> 0.13797486 | E4: =+E3/$B$3-1 -> 0.12629931 | F4: =+F3/$B$3-1 -> 0.11947893 | G4: =+G3/$B$3-1 -> 0.10844421 | H4: =+H3/$B$3-1 -> 0.097793457
A5: aditivo | B5: =+RSV_CIA!L15 -> 8097936.5 | C5: =+RSV_CIA!M15 -> 9259695.1 | D5: =+RSV_CIA!N15 -> 9166540 | E5: =+RSV_CIA!O15 -> 9076384 | F5: =+RSV_CIA!P15 -> 9023774.4 | G5: =+RSV_CIA!Q15 -> 8938513.7 | H5: =+RSV_CIA!R15 -> 8856117.7
C6: =+C5/$B$5-1 -> 0.14346354 | D6: =+D5/$B$5-1 -> 0.13195998 | E6: =+E5/$B$5-1 -> 0.12082676 | F6: =+F5/$B$5-1 -> 0.1143301 | G6: =+G5/$B$5-1 -> 0.10380141 | H6: =+H5/$B$5-1 -> 0.093626468
B9: Multiplicativo | H9: Multiplicativo | N9: Aditivo
B10: Actual-2023 | D10: -1693968.2 | H10: Actual-2024 | J10: =+I12-I17 -> -1117311.6 | N10: Actual-2024 | P10: =+O12-O17 -> -1068603.5
B11: Deslizamiento | C11: Reserva | D11: Impacto | H11: Deslizamiento | I11: Reserva | J11: Impacto | K11: =+RSV_CIA!B31 -> 7822344.6 | L11: =I12/K11-1 -> 0.035231371 | N11: Deslizamiento | O11: Reserva | P11: Impacto | Q11: =+RSV_CIA!B31 -> 7822344.6 | R11: =O12/Q11-1 -> 0.035231371
B12: - | C12: 7946317.9 | D12: Base | H12: - | I12: =+B3 -> 8097936.5 | J12: Base | N12: - | O12: =+B5 -> 8097936.5 | P12: Base | T12: 6580185.8
A13: ESC1 | B13: 0.0131 | C13: 9281458.1 | D13: 0.16801998 | E13: =+C13-$C$12 -> 1335140.2 | F13: =+$D$18-#REF! -> #REF! | G13: ESC1 | H13: 0.0131 | I13: =+H3 -> 8889861.7 | J13: =I13/$I$12-1 -> 0.097793457 | K13: =+I13-$I$12 -> 791925.21 | L13: =+$J$18-D25 -> 0.15004355 | M13: ESC1 | N13: 0.0131 | O13: =+H5 -> 8856117.7 | P13: =O13/$O$12-1 -> 0.093626468 | Q13: =+O13-$O$12 -> 758181.2 | R13: =+$P$18-P25 -> 0.14346354
A14: ESC0 | B14: 0.0141 | C14: 9377185.2 | D14: 0.1800667 | E14: =+C14-$C$12 -> 1430867.2 | F14: =+$D$18-D13 -> 0.058596435 | G14: ESC0 | H14: 0.0141 | I14: =+G3 -> 8976110.9 | J14: =I14/$I$12-1 -> 0.10844421 | K14: =+I14-$I$12 -> 878174.33 | L14: =+$J$18-J13 -> 0.052250092 | M14: ESC0 | N14: 0.0141 | O14: =+G5 -> 8938513.7 | P14: =O14/$O$12-1 -> 0.10380141 | Q14: =+O14-$O$12 -> 840577.2 | R14: =+$P$18-P13 -> 0.04983707
A15: ESC2 | B15: 0.0151 | C15: 9475883.8 | D15: 0.19248738 | E15: =+C15-$C$12 -> 1529565.9 | F15: =+$D$18-D14 -> 0.046549714 | G15: ESC2 | H15: 0.0151 | I15: =+F3 -> 9065469.3 | J15: =I15/$I$12-1 -> 0.11947893 | K15: =+I15-$I$12 -> 967532.75 | L15: =+$J$18-J14 -> 0.041599339 | M15: ESC2 | N15: 0.0151 | O15: =+F5 -> 9023774.4 | P15: =O15/$O$12-1 -> 0.1143301 | Q15: =+O15-$O$12 -> 925837.86 | R15: =+$P$18-P14 -> 0.039662131
A16: ESC1 | B16: 0.0157 | C16: 9536658.8 | D16: 0.20013558 | E16: =+C16-$C$12 -> 1590340.9 | F16: =+$D$18-D15 -> 0.034129035 | G16: ESC1 | H16: 0.0157 | I16: =+E3 -> 9120700.3 | J16: =I16/$I$12-1 -> 0.12629931 | K16: =+I16-$I$12 -> 1022763.8 | L16: =+$J$18-J15 -> 0.030564624 | M16: ESC1 | N16: 0.0157 | O16: =+E5 -> 9076384 | P16: =O16/$O$12-1 -> 0.12082676 | Q16: =+O16-$O$12 -> 978447.45 | R16: =+$P$18-P15 -> 0.029133442
A17: ESC0 | B17: 0.016742824 | C17: 9640286.1 | D17: 0.21317649 | E17: =+C17-$C$12 -> 1693968.2 | F17: =+$D$18-D16 -> 0.026480838 | G17: ESC0 | H17: 0.016742824 | I17: =+D3 -> 9215248.1 | J17: =I17/$I$12-1 -> 0.13797486 | K17: =+I17-$I$12 -> 1117311.6 | L17: =+$J$18-J16 -> 0.023744237 | M17: ESC0 | N17: 0.016742824 | O17: =+D5 -> 9166540 | P17: =O17/$O$12-1 -> 0.13195998 | Q17: =+O17-$O$12 -> 1068603.5 | R17: =+$P$18-P16 -> 0.022636776
A18: ESC2 | B18: 0.0177 | C18: 9747084 | D18: 0.22661641 | E18: =+C18-$C$12 -> 1800766.1 | F18: =+$D$18-D17 -> 0.013439923 | G18: ESC2 | H18: 0.0177 | I18: =+C3 -> 9312979.7 | J18: =I18/$I$12-1 -> 0.15004355 | K18: =+I18-$I$12 -> 1215043.1 | L18: =+$J$18-J17 -> 0.012068694 | M18: ESC2 | N18: 0.0177 | O18: =+C5 -> 9259695.1 | P18: =O18/$O$12-1 -> 0.14346354 | Q18: =+O18-$O$12 -> 1161758.6 | R18: =+$P$18-P17 -> 0.011503562

Sheet Res_CIA_TPO
A1: Desliza Multi | B1: 0 | C1: =+B17 -> 0.0177 | D1: =+B16 -> 0.016742824 | E1: =+B15 -> 0.0157 | F1: 0.0151 | G1: 0.0141 | H1: 0.0131
A2: Tasa | B2: Sin deslizamiento | C2: Con deslizamiento + 10 pt basico | D2: Con deslizamiento | E2: Con deslizamiento - 10 pt basico | F2: Con deslizamiento + 10 pt basico | G2: Con deslizamiento | H2: Con deslizamiento - 10 pt basico
A3: vejez | B3: =+RSV_CIA_TPO!B15 -> 2093952.1 | C3: =+RSV_CIA_TPO!C15 -> 2346029.7 | D3: =+RSV_CIA_TPO!D15 -> 2326043.3 | E3: =+RSV_CIA_TPO!E15 -> 2306606.2 | F3: =+RSV_CIA_TPO!F15 -> 2295204.4 | G3: =+RSV_CIA_TPO!G15 -> 2276721.6 | H3: =+RSV_CIA_TPO!H15 -> 2258811.3 | J3: =+C3/$B$3-1 -> 0.12038369 | K3: =+D3/$B$3-1 -> 0.11083882 | L3: =+E3/$B$3-1 -> 0.10155636 | M3: =+F3/$B$3-1 -> 0.096111239 | N3: =+G3/$B$3-1 -> 0.087284489 | O3: =+H3/$B$3-1 -> 0.07873114
A4: sobre | B4: =+RSV_CIA_TPO!K15 -> 5971564.8 | C4: =+RSV_CIA_TPO!L15 -> 6932967.2 | D4: =+RSV_CIA_TPO!M15 -> 6855233.7 | E4: =+RSV_CIA_TPO!N15 -> 6780136.3 | F4: =+RSV_CIA_TPO!O15 -> 6736317.2 | G4: =+RSV_CIA_TPO!P15 -> 6665461 | H4: =+RSV_CIA_TPO!Q15 -> 6597146.8 | J4: =+C4/$B$4-1 -> 0.16099673 | K4: =+D4/$B$4-1 -> 0.14797947 | L4: =+E4/$B$4-1 -> 0.13540363 | M4: =+F4/$B$4-1 -> 0.12806567 | N4: =+G4/$B$4-1 -> 0.11620006 | O4: =+H4/$B$4-1 -> 0.10476016
A5: aux | B5: =+RSV_CIA_TPO!T15 -> 32419.691 | C5: =+RSV_CIA_TPO!U15 -> 33982.785 | D5: =+RSV_CIA_TPO!V15 -> 33971.177 | E5: =+RSV_CIA_TPO!W15 -> 33957.808 | F5: =+RSV_CIA_TPO!X15 -> 33947.702 | G5: =+RSV_CIA_TPO!Y15 -> 33928.313 | H5: =+RSV_CIA_TPO!Z15 -> 33903.603 | I5: Verificar | J5: =+C5/$B$5-1 -> 0.048214346 | K5: =+D5/$B$5-1 -> 0.047856286 | L5: =+E5/$B$5-1 -> 0.047443923 | M5: =+F5/$B$5-1 -> 0.047132203 | N5: =+G5/$B$5-1 -> 0.046534137 | O5: =+H5/$B$5-1 -> 0.045771931
A6: total | B6: =+RSV_CIA_TPO!AC15 -> 8097936.5 | C6: =+RSV_CIA_TPO!AD15 -> 9312979.7 | D6: =+RSV_CIA_TPO!AE15 -> 9215248.1 | E6: =+RSV_CIA_TPO!AF15 -> 9120700.3 | F6: =+RSV_CIA_TPO!AG15 -> 9065469.3 | G6: =+RSV_CIA_TPO!AH15 -> 8976110.9 | H6: =+RSV_CIA_TPO!AI15 -> 8889861.7 | J6: =+C6/$B$6-1 -> 0.15004355 | K6: =+D6/$B$6-1 -> 0.13797486 | L6: =+E6/$B$6-1 -> 0.12629931 | M6: =+F6/$B$6-1 -> 0.11947893 | N6: =+G6/$B$6-1 -> 0.10844421 | O6: =+H6/$B$6-1 -> 0.097793457
B7: =+SUM(B3:B5)-B6 -> 0 | C7: =+SUM(C3:C5)-C6 -> 0.035399999 | D7: =+SUM(D3:D5)-D6 -> 0.033485647 | E7: =+SUM(E3:E5)-E6 -> 0.031400001 | F7: =+SUM(F3:F5)-F6 -> 0.030200001 | G7: =+SUM(G3:G5)-G6 -> 0.028199999 | H7: =+SUM(H3:H5)-H6 -> 0.0262
B8: vejez | G8: sobre | L8: Aux | Q8: Total Multiplicativo
B9: Actual-2024 | D9: =+C11-C16 -> -232091.18 | F9: verificar | G9: Actual-2024 | I9: =+H11-H16 -> -883668.99 | J9: =+J10+E10 -> 7511262.3 | L9: Actual-2024 | N9: =+M11-M16 -> -1551.486 | Q9: Actual-2024 | S9: =+R11-R16 -> -1117311.6 | T9: =+(T10-O10-J10-E10)/T10 -> 0.036588596
B10: Deslizamiento | C10: Reserva | D10: Impacto | E10: =+RSV_CIA_TPO!$B$65 -> 2193976.1 | F10: =C11/E10-1 -> -0.045590315 | G10: Deslizamiento | H10: Reserva | I10: Impacto | J10: =+RSV_CIA_TPO!$C$65 -> 5317286.1 | K10: =H11/J10-1 -> 0.12304747 | L10: Deslizamiento | M10: Reserva | N10: Impacto | O10: =+RSV_CIA_TPO!$D$65 -> 24873.722 | P10: =M11/O10-1 -> 0.3033711 | Q10: Deslizamiento | R10: Reserva | S10: Impacto | T10: =+RSV_CIA_TPO!$E$65 -> 7822344.6 | U10: =R11/T10-1 -> 0.035231371
B11: - | C11: =+B3 -> 2093952.1 | D11: Base | G11: - | H11: =+B4 -> 5971564.8 | I11: Base | L11: - | M11: =+B5 -> 32419.691 | N11: Base | Q11: - | R11: =+B6 -> 8097936.5 | S11: Base | W11: Comparación escenraio
A12: ESC1 | B12: 0.0131 | C12: =+H3 -> 2258811.3 | D12: =C12/$C$11-1 -> 0.07873114 | E12: =+C12-$C$11 -> 164859.23 | G12: 0.0131 | H12: =+H4 -> 6597146.8 | I12: =H12/$H$11-1 -> 0.10476016 | J12: =+H12-$H$11 -> 625582.09 | L12: 0.0131 | M12: =+H5 -> 33903.603 | N12: =M12/$M$11-1 -> 0.045771931 | O12: =+M12-$M$11 -> 1483.9119 | Q12: 0.0131 | R12: =+H6 -> 8889861.7 | S12: =R12/$R$11-1 -> 0.097793457 | T12: =+R12-$M$11 -> 8857442 | W12: =R31/R12-1 -> 0.0054727506
A13: ESC0 | B13: 0.0141 | C13: =+G3 -> 2276721.6 | D13: =C13/$C$11-1 -> 0.087284489 | E13: =+C13-$C$11 -> 182769.54 | F13: =-D$12+D13 -> 0.0085533496 | G13: 0.0141 | H13: =+G4 -> 6665461 | I13: =H13/$H$11-1 -> 0.11620006 | J13: =+H13-$H$11 -> 693896.2 | K13: =-I$12+I13 -> 0.011439901 | L13: 0.0141 | M13: =+G5 -> 33928.313 | N13: =M13/$M$11-1 -> 0.046534137 | O13: =+M13-$M$11 -> 1508.6223 | P13: =-N$12+N13 -> 0.00076220542 | Q13: 0.0141 | R13: =+G6 -> 8976110.9 | S13: =R13/$R$11-1 -> 0.10844421 | T13: =+R13-$M$11 -> 8943691.2 | U13: =-S$12+S13 -> 0.010650753 | W13: =R32/R13-1 -> 0.0053100429
A14: ESC2 | B14: 0.0151 | C14: =+F3 -> 2295204.4 | D14: =C14/$C$11-1 -> 0.096111239 | E14: =+C14-$C$11 -> 201252.33 | F14: =-D$12+D14 -> 0.0173801 | G14: 0.0151 | H14: =+F4 -> 6736317.2 | I14: =H14/$H$11-1 -> 0.12806567 | J14: =+H14-$H$11 -> 764752.44 | K14: =-I$12+I14 -> 0.023305508 | L14: 0.0151 | M14: =+F5 -> 33947.702 | N14: =M14/$M$11-1 -> 0.047132203 | O14: =+M14-$M$11 -> 1528.0114 | P14: =-N$12+N14 -> 0.0013602713 | Q14: 0.0151 | R14: =+F6 -> 9065469.3 | S14: =R14/$R$11-1 -> 0.11947893 | T14: =+R14-$M$11 -> 9033049.6 | U14: =-S$12+S14 -> 0.021685468 | W14: =R33/R14-1 -> 0.0012039859
A15: ESC1 | B15: 0.0157 | C15: =+E3 -> 2306606.2 | D15: =C15/$C$11-1 -> 0.10155636 | E15: =+C15-$C$11 -> 212654.16 | F15: =-D$12+D15 -> 0.022825224 | G15: 0.0157 | H15: =+E4 -> 6780136.3 | I15: =H15/$H$11-1 -> 0.13540363 | J15: =+H15-$H$11 -> 808571.57 | K15: =-I$12+I15 -> 0.030643473 | L15: 0.0157 | M15: =+E5 -> 33957.808 | N15: =M15/$M$11-1 -> 0.047443923 | O15: =+M15-$M$11 -> 1538.1173 | P15: =-N$12+N15 -> 0.0016719915 | Q15: 0.0157 | R15: =+E6 -> 9120700.3 | S15: =R15/$R$11-1 -> 0.12629931 | T15: =+R15-$M$11 -> 9088280.6 | U15: =-S$12+S15 -> 0.028505856 | W15: =R34/R15-1 -> 0.0050266251
A16: ESC0 | B16: 0.016742824 | C16: =+D3 -> 2326043.3 | D16: =C16/$C$11-1 -> 0.11083882 | E16: =+C16-$C$11 -> 232091.18 | F16: =-D$12+D16 -> 0.032107682 | G16: 0.016742824 | H16: =+D4 -> 6855233.7 | I16: =H16/$H$11-1 -> 0.14797947 | J16: =+H16-$H$11 -> 883668.99 | K16: =-I$12+I16 -> 0.043219309 | L16: 0.016742824 | M16: =+D5 -> 33971.177 | N16: =M16/$M$11-1 -> 0.047856286 | O16: =+M16-$M$11 -> 1551.486 | P16: =-N$12+N16 -> 0.0020843549 | Q16: 0.016742824 | R16: =+D6 -> 9215248.1 | S16: =R16/$R$11-1 -> 0.13797486 | T16: =+R16-$M$11 -> 9182828.5 | U16: =-S$12+S16 -> 0.040181399 | W16: =R35/R16-1 -> 0.0048232019
A17: ESC2 | B17: 0.0177 | C17: =+C3 -> 2346029.7 | D17: =C17/$C$11-1 -> 0.12038369 | E17: =+C17-$C$11 -> 252077.67 | F17: =-D$12+D17 -> 0.041652547 | G17: 0.0177 | H17: =+C4 -> 6932967.2 | I17: =H17/$H$11-1 -> 0.16099673 | J17: =+H17-$H$11 -> 961402.41 | K17: =-I$12+I17 -> 0.05623657 | L17: 0.0177 | M17: =+C5 -> 33982.785 | N17: =M17/$M$11-1 -> 0.048214346 | O17: =+M17-$M$11 -> 1563.0942 | P17: =-N$12+N17 -> 0.002442415 | Q17: 0.0177 | R17: =+C6 -> 9312979.7 | S17: =R17/$R$11-1 -> 0.15004355 | T17: =+R17-$M$11 -> 9280560 | U17: =-S$12+S17 -> 0.052250092
A19: Desliza Aditiva | B19: 0 | C19: =+B35 -> 0.0177 | D19: =+B34 -> 0.016742824 | E19: =+B33 -> 0.0157 | F19: 0.0151 | G19: 0.0141 | H19: 0.0131
A20: Tasa | B20: Sin deslizamiento | C20: Con deslizamiento + 10 pt basico | D20: Con deslizamiento | E20: Con deslizamiento - 10 pt basico | F20: Con deslizamiento + 10 pt basico | G20: Con deslizamiento | H20: Con deslizamiento - 10 pt basico
A21: vejez | B21: =+RSV_CIA_TPO!B33 -> 2093952.1 | C21: =+RSV_CIA_TPO!C33 -> 2335023.8 | D21: =+RSV_CIA_TPO!D33 -> 2315924.3 | E21: =+RSV_CIA_TPO!E33 -> 2297353.6 | F21: =+RSV_CIA_TPO!F33 -> 2286488.9 | G21: =+RSV_CIA_TPO!G33 -> 2268834.5 | H21: =+RSV_CIA_TPO!H33 -> 2251703.5 | J21: =+C21/$B$21-1 -> 0.11512764 | K21: =+D21/$B$21-1 -> 0.10600637 | L21: =+E21/$B$21-1 -> 0.097137643 | M21: =+F21/$B$21-1 -> 0.091949024 | N21: =+G21/$B$21-1 -> 0.083517868 | O21: =+H21/$B$21-1 -> 0.075336676
A22: sobre | B22: =+RSV_CIA_TPO!K33 -> 5971564.8 | C22: =+RSV_CIA_TPO!L33 -> 6890694.1 | D22: =+RSV_CIA_TPO!M33 -> 6816651.2 | E22: =+RSV_CIA_TPO!N33 -> 6745080.5 | F22: =+RSV_CIA_TPO!O33 -> 6703345.3 | G22: =+RSV_CIA_TPO!P33 -> 6635761 | H22: =+RSV_CIA_TPO!Q33 -> 6570522.1 | J22: =+C22/$B$22-1 -> 0.15391767 | K22: =+D22/$B$22-1 -> 0.14151842 | L22: =+E22/$B$22-1 -> 0.12953317 | M22: =+F22/$B$22-1 -> 0.12254418 | N22: =+G22/$B$22-1 -> 0.11122651 | O22: =+H22/$B$22-1 -> 0.10030157
A23: aux | B23: =+RSV_CIA_TPO!T33 -> 32419.691 | C23: =+RSV_CIA_TPO!U33 -> 33977.264 | D23: =+RSV_CIA_TPO!V33 -> 33971.177 | E23: =+RSV_CIA_TPO!W33 -> 33949.868 | F23: =+RSV_CIA_TPO!X33 -> 33940.203 | G23: =+RSV_CIA_TPO!Y33 -> 33918.219 | H23: =+RSV_CIA_TPO!Z33 -> 33892.218 | I23: Verificar | J23: =+C23/$B$23-1 -> 0.04804404 | K23: =+D23/$B$23-1 -> 0.047856286 | L23: =+E23/$B$23-1 -> 0.047198998 | M23: =+F23/$B$23-1 -> 0.046900871 | N23: =+G23/$B$23-1 -> 0.046222764 | O23: =+H23/$B$23-1 -> 0.045420747
A24: total | B24: =+RSV_CIA_TPO!AC33 -> 8097936.5 | C24: =+RSV_CIA_TPO!AD33 -> 9259695.1 | D24: =+RSV_CIA_TPO!AE33 -> 9166546.7 | E24: =+RSV_CIA_TPO!AF33 -> 9076384 | F24: =+RSV_CIA_TPO!AG33 -> 9023774.4 | G24: =+RSV_CIA_TPO!AH33 -> 8938513.7 | H24: =+RSV_CIA_TPO!AI33 -> 8856117.7 | J24: =+C24/$B$24-1 -> 0.14346354 | K24: =+D24/$B$24-1 -> 0.1319608 | L24: =+E24/$B$24-1 -> 0.12082676 | M24: =+F24/$B$24-1 -> 0.1143301 | N24: =+G24/$B$24-1 -> 0.10380141 | O24: =+H24/$B$24-1 -> 0.093626468
B25: =+SUM(B21:B23)-B24 -> 0 | C25: =+SUM(C21:C23)-C24 -> 0.035400001 | D25: =+SUM(D21:D23)-D24 -> 0.033485645 | E25: =+SUM(E21:E23)-E24 -> 0.031399999 | F25: =+SUM(F21:F23)-F24 -> 0.030200001 | G25: =+SUM(G21:G23)-G24 -> 0.0141 | H25: =+SUM(H21:H23)-H24 -> 0.026199998
B26: vejez | G26: sobre | L26: Aux | Q26: Total Aditivo
B27: Actual-2024 | D27: =+C29-C34 -> -221972.27 | F27: verificar | G27: Actual-2024 | I27: =+H29-H34 -> -845086.44 | J27: =+J28+E28 -> 7511262.3 | L27: Actual-2024 | N27: =+M29-M34 -> -1551.486 | Q27: Actual-2024 | S27: =+R29-R34 -> -1068610.2 | T27: =+(T28-O28-J28-E28)/T28 -> 0.036588596
B28: Deslizamiento | C28: Reserva | D28: Impacto | E28: =+RSV_CIA_TPO!$B$65 -> 2193976.1 | F28: =C29/E28-1 -> -0.045590315 | G28: Deslizamiento | H28: Reserva | I28: Impacto | J28: =+RSV_CIA_TPO!$C$65 -> 5317286.1 | K28: =H29/J28-1 -> 0.12304747 | L28: Deslizamiento | M28: Reserva | N28: Impacto | O28: =+RSV_CIA_TPO!$D$65 -> 24873.722 | P28: =M29/O28-1 -> 0.3033711 | Q28: Deslizamiento | R28: Reserva | S28: Impacto | T28: =+RSV_CIA_TPO!$E$65 -> 7822344.6 | U28: =R29/T28-1 -> 0.035231371
B29: - | C29: =+B21 -> 2093952.1 | D29: Base | G29: - | H29: =+B22 -> 5971564.8 | I29: Base | L29: - | M29: =+B23 -> 32419.691 | N29: Base | Q29: - | R29: =+B24 -> 8097936.5 | S29: Base
A30: ESC1 | B30: 0.0131 | C30: =+H21 -> 2251703.5 | D30: =C30/$C$11-1 -> 0.075336676 | E30: =+C30-$C$29 -> 157751.39 | G30: 0.0131 | H30: =+H22 -> 6570522.1 | I30: =H30/$H$11-1 -> 0.10030157 | J30: =+H30-$H$29 -> 598957.31 | L30: 0.0131 | M30: =+H23 -> 33892.218 | N30: =M30/$M$11-1 -> 0.045420747 | O30: =+M30-$M$29 -> 1472.5266 | Q30: 0.0131 | R30: =+H24 -> 8856117.7 | S30: =R30/$R$11-1 -> 0.093626468 | T30: =+R30-$R$29 -> 758181.2
A31: ESC0 | B31: 0.0141 | C31: =+G21 -> 2268834.5 | D31: =C31/$C$11-1 -> 0.083517868 | E31: =+C31-$C$29 -> 174882.41 | F31: =-D$30+D31 -> 0.0081811911 | G31: 0.0141 | H31: =+G22 -> 6635761 | I31: =H31/$H$11-1 -> 0.11122651 | J31: =+H31-$H$29 -> 664196.28 | K31: =-I$30+I31 -> 0.010924937 | L31: 0.0141 | M31: =+G23 -> 33918.219 | N31: =M31/$M$11-1 -> 0.046222764 | O31: =+M31-$M$29 -> 1498.5277 | P31: =-N$30+N31 -> 0.00080201679 | Q31: 0.0141 | R31: =+G24 -> 8938513.7 | S31: =R31/$R$11-1 -> 0.10380141 | T31: =+R31-$R$29 -> 840577.2 | U31: =-S$30+S31 -> 0.010174938
A32: ESC2 | B32: 0.0151 | C32: =+F21 -> 2286488.9 | D32: =C32/$C$11-1 -> 0.091949024 | E32: =+C32-$C$29 -> 192536.85 | F32: =-D$30+D32 -> 0.016612348 | G32: 0.0151 | H32: =+F22 -> 6703345.3 | I32: =H32/$H$11-1 -> 0.12254418 | J32: =+H32-$H$29 -> 731780.53 | K32: =-I$30+I32 -> 0.022242617 | L32: 0.0151 | M32: =+F23 -> 33940.203 | N32: =M32/$M$11-1 -> 0.046900871 | O32: =+M32-$M$29 -> 1520.5117 | P32: =-N$30+N32 -> 0.0014801236 | Q32: 0.0151 | R32: =+F24 -> 9023774.4 | S32: =R32/$R$11-1 -> 0.1143301 | T32: =+R32-$R$29 -> 925837.86 | U32: =-S$30+S32 -> 0.020703628
A33: ESC1 | B33: 0.0157 | C33: =+E21 -> 2297353.6 | D33: =C33/$C$11-1 -> 0.097137643 | E33: =+C33-$C$29 -> 203401.57 | F33: =-D$30+D33 -> 0.021800966 | G33: 0.0157 | H33: =+E22 -> 6745080.5 | I33: =H33/$H$11-1 -> 0.12953317 | J33: =+H33-$H$29 -> 773515.74 | K33: =-I$30+I33 -> 0.029231606 | L33: 0.0157 | M33: =+E23 -> 33949.868 | N33: =M33/$M$11-1 -> 0.047198998 | O33: =+M33-$M$29 -> 1530.1769 | P33: =-N$30+N33 -> 0.0017782507 | Q33: 0.0157 | R33: =+E24 -> 9076384 | S33: =R33/$R$11-1 -> 0.12082676 | T33: =+R33-$R$29 -> 978447.45 | U33: =-S$30+S33 -> 0.027200294
A34: ESC0 | B34: 0.016742824 | C34: =+D21 -> 2315924.3 | D34: =C34/$C$11-1 -> 0.10600637 | E34: =+C34-$C$29 -> 221972.27 | F34: =-D$30+D34 -> 0.030669698 | G34: 0.016742824 | H34: =+D22 -> 6816651.2 | I34: =H34/$H$11-1 -> 0.14151842 | J34: =+H34-$H$29 -> 845086.44 | K34: =-I$30+I34 -> 0.041216857 | L34: 0.016742824 | M34: =+D23 -> 33971.177 | N34: =M34/$M$11-1 -> 0.047856286 | O34: =+M34-$M$29 -> 1551.486 | P34: =-N$30+N34 -> 0.002435539 | Q34: 0.016742824 | R34: =+D24 -> 9166546.7 | S34: =R34/$R$11-1 -> 0.1319608 | T34: =+R34-$R$29 -> 1068610.2 | U34: =-S$30+S34 -> 0.038334329
